Workbook

Sheet Cover Sheet
A1: Company Master Budget and Financial Statement
A5: Company: | B5: Albert Enterprises
A6: Prepared By: | B6: Jeffrey Hill
A7: Date Prepared: | B7: 45439
A9: Budget Period: | B9: Q1 2023
A11: Table of Contents
A12: 2022 Balance Sheet
A13: Additional Information
A14: Sales Budget
A15: Expected Cash Collections
A16: Production Budget
A17: Direct Materials Budget
A18: Cash Disbursement for Materials
A19: Direct Labor Budget
A20: Manufacturing Overhead Budget
A21: Selling & Administrative Budget
A22: Cash Budget
... A24: Budgeted Balance Sheet

Sheet 2022 Balance Sheet
A1: Albert Enterprises
A2: Balance Sheet
A3: 44926
A5: Assets | E5: =A3 -> 44926
A6: Cash | E6: 110000
A7: Accounts Receivable | E7: 1770000
A8: Raw Materials | E8: 163200
A9: Finished Goods | E9: 540000
A10: Total Current Assets | E10: =SUM(E6:E9) -> 2583200
A11: Net Property, Plant, and Equipment | E11: 1200000
A12: Total Assets | E12: =SUM(E10:E11) -> 3783200
A13: Liabilities & Stockholder Equity
A14: Accounts Payable | E14: 571200
A15: Total Current Liabilities | E15: =SUM(E14) -> 571200
A16: Notes Payable | E16: 0
A17: Total Liabilities | E17: =E15+E16 -> 571200
A18: Common Stock | E18: 1500000
A19: Retained Earnings | E19: 1712000
A20: Total Liabilities & Stockholder Equity | E20: =SUM(E17:E19) -> 3783200

Sheet Additional Information
A1: Additional Information
A2: Sales:
A3: November, 2022 Actual Sales: | E3: 1500000
A4: December, 2022 Actual Sales: | E4: 2100000
A5: Budgeted Sales 2023 (in Units):
A6: January | E6: 30000
A7: February | E7: 40000
A8: March | E8: 50000
A9: April | E9: 45000
A10: May | E10: 35000
A11: Budgeted Selling Price (per unit) | E11: 60
A12: Collectable Percentage in Sale Month | E12: 0.3
A13: Collectable 1 Month (NET30) | E13: 0.5
A14: Collectable 2 Months (NET60) | E14: 0.2
A15: Inventory
A16: Finished Goods Inventory | E16: 0.4
A17: Production
A18: Material Requirements (in kg per unit) | E18: 3
A19: Raw Material Inventory of Next Month Need | E19: 0.2
A20: Raw Material Price (per kg) | E20: 8
A21: Material Purchase in Production Month | E21: 0.3
A22: Material Purchase Following Month | E22: 0.7
A23: Direct Unit Labor (hours) | E23: 2
A24: Direct Labor Rate (Wage per hour) | E24: 6
A25: Manufacturing
A26: Variable Overhead (per direct labor hour) | E26: 2
A27: Fixed Manufacturing Overhead (OH) | E27: 200000
A28: Fixed Monthly OH Depreciation | E28: 25000
A29: Selling Expenses
A30: Variable Selling Expense (per unit sold) | E30: 2
A31: Fixed Selling & Administrative (S&A) Expense | E31: 120000
A32: S&A Monthly Depriciation | E32: 20000
A33: Disbursements
A34: Equipment Purchase, January | E34: 300000
A35: Dividends, March | E35: 150000
A36: Cash
A37: Balance Maintenance Requirement | E37: 50000
A38: Line of Credit:
A39: Annual Interest Rate | E39: 0.12
A40: Borrowed Incremental Amount | E40: 5000
...

Sheet Sales Budget
A1: Sales Budget
C2: January | E2: February | G2: March | I2: Quarter (Q1)
A3: Budgeted Sales in Units | C3: ='Additional Information'!E6 -> 30000 | E3: ='Additional Information'!E7 -> 40000 | G3: ='Additional Information'!E8 -> 50000 | I3: =SUM(C3,E3,G3) -> 120000
A4: Selling Price per Unit | C4: ='Additional Information'!E11 -> 60 | E4: ='Additional Information'!E11 -> 60 | G4: ='Additional Information'!E11 -> 60 | I4: ='Additional Information'!E11 -> 60
A5: Total Budget Sales | C5: =C3*C4 -> 1800000 | E5: =E3*E4 -> 2400000 | G5: =G3*G4 -> 3000000 | I5: =SUM(C5,E5,G5) -> 7200000

Sheet Expected Cash Collections
A1: Expected Cash Collections
A2: Schedule of Expected Cash Collections
A3: Accounts Receivable 12/31 | C3: =C32 -> 1350000 | E3: =E32 -> 420000 | G3: =G32 -> 0 | I3: =I32 -> 1770000
A4: January Sales:
A5: Monthly 30% of $1,800,000 | C5: ='Sales Budget'!C5*'Additional Information'!E12 -> 540000 | I5: =SUM(C5,E5,G5) -> 540000
A6: 50% of $1,800,000 | E6: ='Sales Budget'!C5*'Additional Information'!E13 -> 900000 | I6: =SUM(C6,E6,G6) -> 900000
A7: 20% of $1,800,000 | G7: ='Sales Budget'!C5*'Additional Information'!E14 -> 360000 | I7: =SUM(C7,E7,G7) -> 360000
A8: February Sales:
A9: Monthly 30% of $2,400,000 | E9: ='Sales Budget'!E5*'Additional Information'!E12 -> 720000 | I9: =SUM(C9,E9,G9) -> 720000
A10: 50% of $2,400,000 | G10: ='Sales Budget'!E5*'Additional Information'!E13 -> 1200000 | I10: =SUM(C10,E10,G10) -> 1200000
A11: March Sales:
A12: Monthly 30% of $3,000,000 | G12: ='Sales Budget'!G5*'Additional Information'!E12 -> 900000 | I12: =SUM(C12,E12,G12) -> 900000
A13: Total | C13: =SUM(C3,C5,C6,C7,C9,C10,C12) -> 1890000 | E13: =SUM(E3,E6,E9,E7,E10,E12) -> 2040000 | G13: =SUM(G3,G6, G7,G10,G12) -> 2460000 | I13: =SUM(I3,I5,I6,I7,I9,I10,I12) -> 6390000
A15: Accounts Receivable Next Quarter
A16: Accounts Receivable 3/31
A17: February Sales:
A18: 20% of $2,400,000 | E18: ='Sales Budget'!E5*'Additional Information'!E14 -> 480000 | I18: =SUM(C18,E18,G18) -> 480000
A19: March Sales:
A20: 50% of $3,000,000 | G20: ='Sales Budget'!G5*'Additional Information'!E13 -> 1500000 | I20: =SUM(C20,E20,G20) -> 1500000
A21: 20% of $3,000,000 | G21: ='Sales Budget'!G5*'Additional Information'!E14 -> 600000 | I21: =SUM(C21,E21,G21) -> 600000
A22: Total Accounts Receivable | C22: =SUM(C18,C20,C21) -> 0 | E22: =SUM(E18,E20,E21) -> 480000 | G22: =SUM(G18,G20,G21) -> 2100000 | I22: =SUM(I18,I20,I21) -> 2580000
A24: Previous Quarter Supporting Calculations
C25: January | E25: February | G25: March | I25: Quarter (Q1)
A26: Accounts Receivable 12/31
A27: November Sales:
A28: 20% of $1,500,000 | C28: ='Additional Information'!E3*'Additional Information'!E14 -> 300000 | I28: =SUM(C28,E28,G28) -> 300000
A29: December Sales
A30: 50% of $2,100,000 | C30: ='Additional Information'!E4*'Additional Information'!E13 -> 1050000 | I30: =SUM(C30,E30,G30) -> 1050000
A31: 20% of $2,100,000 | E31: ='Additional Information'!E4*'Additional Information'!E14 -> 420000 | I31: =SUM(C31,E31,G31) -> 420000
A32: Total Accounts Receivable | C32: =SUM(C28,C30,C31) -> 1350000 | E32: =SUM(E28,E30,E31) -> 420000 | G32: =SUM(G28,G30,G31) -> 0 | I32: =SUM(C32,E32,G32) -> 1770000

Sheet Production Budget
A1: Production Budget
C2: January | E2: February | G2: March | I2: Quarter (Q1)
A3: Budgeted Sales | C3: ='Additional Information'!E6 -> 30000 | E3: ='Additional Information'!E7 -> 40000 | G3: ='Additional Information'!E8 -> 50000 | I3: =SUM(C3,E3,G3) -> 120000
A4: Add: Desired Inventory | C4: =E3*C19 -> 16000 | E4: =G3*C19 -> 20000 | G4: =C11*C19 -> 18000 | I4: =G4 -> 18000
A5: Total Needs | C5: =SUM(C3,C4) -> 46000 | E5: =SUM(E3,E4) -> 60000 | G5: =SUM(G3,G4) -> 68000 | I5: =I3+I4 -> 138000
A6: Less beginning Inventory | C6: =C20 -> 12000 | E6: ='Additional Information'!E7*'Additional Information'!E16 -> 16000 | G6: ='Additional Information'!E8*'Additional Information'!E16 -> 20000 | I6: =C6 -> 12000
A7: Required Production | C7: =C5-C6 -> 34000 | E7: =E5-E6 -> 44000 | G7: =G5-G6 -> 48000 | I7: =I5-I6 -> 126000
A10: Following Month Calculations (April)
A11: Budgeted Sales | C11: ='Additional Information'!E9 -> 45000
A12: Add: Desired Inventory | C12: ='Additional Information'!E10*'Additional Information'!E16 -> 14000
A13: Total Needs | C13: =SUM(C11,C12) -> 59000
A14: Less Beginning Inventory | C14: =C11*'Additional Information'!E16 -> 18000
A15: Required Production | C15: =C13-C14 -> 41000
A17: Beginning Calculations (December)
A18: Budgeted Sales | C18: ='Additional Information'!E6 -> 30000
A19: Desired Finished Goods Inventory | C19: ='Additional Information'!E16 -> 0.4
A20: Finished Goods Inventory Total | C20: =C18*C19 -> 12000

Sheet Direct Mats Budget
A1: Direct Materials Budget
C2: January | E2: February | G2: March | I2: Quarter (Q1)
A3: Production (units) | C3: ='Production Budget'!C7 -> 34000 | E3: ='Production Budget'!E7 -> 44000 | G3: ='Production Budget'!G7 -> 48000 | I3: =SUM(C3,E3,G3) -> 126000
A4: Material per units (kg) | C4: ='Additional Information'!E18 -> 3 | E4: ='Additional Information'!E18 -> 3 | G4: ='Additional Information'!E18 -> 3 | I4: ='Additional Information'!E18 -> 3
A5: Production needs (kg) | C5: =C3*C4 -> 102000 | E5: =E3*E4 -> 132000 | G5: =G3*G4 -> 144000 | I5: =I3*I4 -> 378000
A6: Add: Desired Ending Inventory (kg) | C6: =E5*E14 -> 26400 | E6: =G5*E14 -> 28800 | G6: =C19*E14 -> 24600 | I6: =G6 -> 24600
A7: Total Need (kg) | C7: =C5+C6 -> 128400 | E7: =E5+E6 -> 160800 | G7: =G5+G6 -> 168600 | I7: =I5+I6 -> 402600
A8: Less: Beginning Inventory (kg) | C8: =C24 -> 20400 | E8: =E5*'Additional Information'!E19 -> 26400 | G8: =G5*'Additional Information'!E19 -> 28800 | I8: =C8 -> 20400
A9: Materials to be purchased | C9: =C7-C8 -> 108000 | E9: =E7-E8 -> 134400 | G9: =G7-G8 -> 139800 | I9: =I7-I8 -> 382200
A11: Raw Material Price | C11: ='Additional Information'!E20 -> 8 | E11: ='Additional Information'!E20 -> 8 | G11: ='Additional Information'!E20 -> 8 | I11: ='Additional Information'!E20 -> 8
A12: Purchase Cost | C12: =C9*C11 -> 864000 | E12: =E9*E11 -> 1075200 | G12: =G9*G11 -> 1118400 | I12: =I9*I11 -> 3057600
A14: Raw Material Inventory of Next Month Need | E14: 0.2
A16: Following Month Calculations (April)
A17: Required Production | C17: ='Production Budget'!C15 -> 41000
A18: April Materials | C18: 3
A19: April Production Needs | C19: =C17*C18 -> 123000
A21: Beginning Calculations (December)
A22: Raw Materials | C22: ='2022 Balance Sheet'!E8 -> 163200
A23: Raw Material Price (per kg) | C23: ='Additional Information'!E20 -> 8
A24: Beginning Inventory (in kg) | C24: =C22/C23 -> 20400

Sheet Cash Disbursement Mats
A1: Cash Disbursement for Materials
C2: January | E2: February | G2: March | I2: Quarter (Q1)
A3: Accounts Payable 12/31 | C3: ='2022 Balance Sheet'!E14 -> 571200 | I3: =SUM(C3,E3,G3) -> 571200
A4: January Purchases:
A5: 30% of $864,000 | C5: ='Direct Mats Budget'!C12*'Additional Information'!E21 -> 259200 | I5: =SUM(C5,E5,G5) -> 259200
A6: 70% of $864,000 | E6: ='Direct Mats Budget'!C12*'Additional Information'!E22 -> 604800 | I6: =SUM(C6,E6,G6) -> 604800
A7: Feburary Purchases:
A8: 30% of $1,075,200 | E8: ='Direct Mats Budget'!E12*'Additional Information'!E21 -> 322560 | I8: =SUM(C8,E8,G8) -> 322560
A9: 70% of $1,075,200 | G9: ='Direct Mats Budget'!E12*'Additional Information'!E22 -> 752640 | I9: =SUM(C9,E9,G9) -> 752640
A10: March Purchases:
A11: 30% of $1,118,400 | G11: ='Direct Mats Budget'!G12*'Additional Information'!E21 -> 335520 | I11: =SUM(C11,E11,G11) -> 335520
A12: Total Cash Disbursements | C12: =SUM(C3,C5,C6,C8,C9,C11) -> 830400 | E12: =SUM(E3,E5,E6,E8,E9,E11) -> 927360 | G12: =SUM(G3,G5,G6,G8,G9,G11) -> 1088160 | I12: =SUM(I3,I5,I6,I8,I9,I11) -> 2845920
A14: Accounts Payable 3/31
A15: 70% of $1,118,400 | G15: ='Direct Mats Budget'!G12*'Additional Information'!E22 -> 782880 | I15: =G15 -> 782880
C17: From Budget Sheet | E17: From Disbursements
A18: Direct Materials Budget Total | C18: ='Direct Mats Budget'!I12 -> 3057600 | E18: =SUM(C5,E6,E8,G9,G11,G15) -> 3057600

Sheet Direct Labor Budget
A1: Direct Labor Budget
C2: January | E2: February | G2: March | I2: Quarter (Q1)
A3: Units of Production | C3: ='Production Budget'!C7 -> 34000 | E3: ='Production Budget'!E7 -> 44000 | G3: ='Production Budget'!G7 -> 48000 | I3: =SUM(C3,E3,G3) -> 126000
A4: Direct labor time per unit | C4: ='Additional Information'!E23 -> 2 | E4: ='Additional Information'!E23 -> 2 | G4: ='Additional Information'!E23 -> 2 | I4: ='Additional Information'!E23 -> 2
A5: Labor hours required | C5: =C3*C4 -> 68000 | E5: =E3*E4 -> 88000 | G5: =G3*G4 -> 96000 | I5: =I3*I4 -> 252000
A6: Hourly wage rate | C6: ='Additional Information'!E24 -> 6 | E6: ='Additional Information'!E24 -> 6 | G6: ='Additional Information'!E24 -> 6 | I6: ='Additional Information'!E24 -> 6
A7: Total Direct Labor Costs | C7: =C5*C6 -> 408000 | E7: =E5*E6 -> 528000 | G7: =G5*G6 -> 576000 | I7: =I5*I6 -> 1512000

Sheet Mfg OH Budget
A1: Manufacturing Overhead Budget
C2: January | E2: February | G2: March | I2: Quarter (Q1)
A3: Budgeted direct labor hours | C3: ='Direct Labor Budget'!C5 -> 68000 | E3: ='Direct Labor Budget'!E5 -> 88000 | G3: ='Direct Labor Budget'!G5 -> 96000 | I3: ='Direct Labor Budget'!I5 -> 252000
A4: Vairable mfg. OH rate | C4: ='Additional Information'!E26 -> 2 | E4: ='Additional Information'!E26 -> 2 | G4: ='Additional Information'!E26 -> 2 | I4: ='Additional Information'!E26 -> 2
A5: Variable mfg. OH costs | C5: =C3*C4 -> 136000 | E5: =E3*E4 -> 176000 | G5: =G3*G4 -> 192000 | I5: =I3*I4 -> 504000
A6: Fixed mfg. OH costs | C6: ='Additional Information'!E27 -> 200000 | E6: ='Additional Information'!E27 -> 200000 | G6: ='Additional Information'!E27 -> 200000 | I6: =SUM(C6,E6,G6) -> 600000
A7: Total mfg. OH costs | C7: =C5+C6 -> 336000 | E7: =E5+E6 -> 376000 | G7: =G5+G6 -> 392000 | I7: =I5+I6 -> 1104000
A8: Less noncash costs | C8: ='Additional Information'!E28 -> 25000 | E8: ='Additional Information'!E28 -> 25000 | G8: ='Additional Information'!E28 -> 25000 | I8: =SUM(C8,E8,G8) -> 75000
A9: Cash disbursement for mfg. OH | C9: =C7-C8 -> 311000 | E9: =E7-E8 -> 351000 | G9: =G7-G8 -> 367000 | I9: =I7-I8 -> 1029000
A12: Total mfg. OH rate | C12: =I7/I3 -> 4.3809524

Sheet Selling Admin Budget
A1: Selling and Administrative Budget
C2: January | E2: February | G2: March | I2: Quarter (Q1)
A3: Budgeted Sales | C3: ='Sales Budget'!C3 -> 30000 | E3: ='Sales Budget'!E3 -> 40000 | G3: ='Sales Budget'!G3 -> 50000 | I3: =SUM(C3,E3,G3) -> 120000
A4: Variable S&A Rate | C4: ='Additional Information'!E30 -> 2 | E4: ='Additional Information'!E30 -> 2 | G4: ='Additional Information'!E30 -> 2 | I4: ='Additional Information'!E30 -> 2
A5: Variable Expenses | C5: =C3*C4 -> 60000 | E5: =E3*E4 -> 80000 | G5: =G3*G4 -> 100000 | I5: =I3*I4 -> 240000
A6: Fixed S&A Expenses | C6: ='Additional Information'!E31 -> 120000 | E6: ='Additional Information'!E31 -> 120000 | G6: ='Additional Information'!E31 -> 120000 | I6: =SUM(C6,E6,G6) -> 360000
A7: Total S&A Expenses | C7: =SUM(C5,C6) -> 180000 | E7: =SUM(E5,E6) -> 200000 | G7: =SUM(G5,G6) -> 220000 | I7: =SUM(I5,I6) -> 600000
A8: Less: Noncash Expenses | C8: ='Additional Information'!E32 -> 20000 | E8: ='Additional Information'!E32 -> 20000 | G8: ='Additional Information'!E32 -> 20000 | I8: =SUM(C8,E8,G8) -> 60000
A9: Cash S&A Expenses | C9: =C7-C8 -> 160000 | E9: =E7-E8 -> 180000 | G9: =G7-G8 -> 200000 | I9: =I7-I8 -> 540000

Sheet Ending Finished Goods Inventory
A1: Ending Finished Goods Inventory Budget
A3: Production Costs per Unit | D3: Quantity | F3: Cost | G3: Total
A4: Direct Materials | D4: ='Additional Information'!E18 -> 3 | E4: kgs. | F4: ='Additional Information'!E20 -> 8 | G4: =D4*F4 -> 24
A5: Direct Labor | D5: ='Additional Information'!E23 -> 2 | E5: hrs. | F5: ='Additional Information'!E24 -> 6 | G5: =D5*F5 -> 12
A6: Manufacturing Overhead | D6: ='Ending Finished Goods Inventory'!D5 -> 2 | E6: hrs. | F6: ='Mfg OH Budget'!C12 -> 4.3809524 | G6: =D6*F6 -> 8.7619048
G7: =SUM(G4:G6) -> 44.761905
A8: Budgeted Finished Good Inventory
A9: Ending Inventory Units | G9: ='Production Budget'!I4 -> 18000
A10: Unit Production Costs | G10: =G7 -> 44.761905
A11: Ending Finished Goods Inventory | G11: =G9*G10 -> 805714.29

Sheet Cash Budget
A1: Cash Budget
C2: January | E2: February | G2: March | I2: Quarter (Q1)
A3: Beginning Cash Balance | C3: ='2022 Balance Sheet'!E6 -> 110000 | E3: =C20 -> 50600 | G3: =E20 -> 53040 | I3: =C3 -> 110000
A4: Add: Cash Collections | C4: ='Expected Cash Collections'!C13 -> 1890000 | E4: ='Expected Cash Collections'!E13 -> 2040000 | G4: ='Expected Cash Collections'!G13 -> 2460000 | I4: =SUM(C4,E4,G4) -> 6390000
A5: Total: Cash Available | C5: =C3+C4 -> 2000000 | E5: =E3+E4 -> 2090600 | G5: =G3+G4 -> 2513040 | I5: =I3+I4 -> 6500000
A6: Less: Cash Disbursements
A7: Materials | C7: ='Cash Disbursement Mats'!C12 -> 830400 | E7: ='Cash Disbursement Mats'!E12 -> 927360 | G7: ='Cash Disbursement Mats'!G12 -> 1088160 | I7: =SUM(C7,E7,G7) -> 2845920
A8: Direct Labor | C8: ='Direct Labor Budget'!C7 -> 408000 | E8: ='Direct Labor Budget'!E7 -> 528000 | G8: ='Direct Labor Budget'!G7 -> 576000 | I8: =SUM(C8,E8,G8) -> 1512000
A9: Manufacturing Overhead | C9: ='Mfg OH Budget'!C9 -> 311000 | E9: ='Mfg OH Budget'!E9 -> 351000 | G9: ='Mfg OH Budget'!G9 -> 367000 | I9: =SUM(C9,E9,G9) -> 1029000
A10: Selling and Administrative | C10: ='Selling Admin Budget'!C9 -> 160000 | E10: ='Selling Admin Budget'!E9 -> 180000 | G10: ='Selling Admin Budget'!G9 -> 200000 | I10: =SUM(C10,E10,G10) -> 540000
A11: Equipment and Purchase | C11: ='Additional Information'!E34 -> 300000 | I11: =SUM(C11,E11,G11) -> 300000
A12: Dividend | G12: ='Additional Information'!E35 -> 150000 | I12: =SUM(C12,E12,G12) -> 150000
A13: Total Disbursements | C13: =SUM(C7:C12) -> 2009400 | E13: =SUM(E7:E12) -> 1986360 | G13: =SUM(G7:G12) -> 2381160 | I13: =SUM(I7:I12) -> 6376920
A14: Excess (Dificiency) | C14: =C5-C13 -> -9400 | E14: =E5-E13 -> 104240 | G14: =G5-G13 -> 131880 | I14: =I5-I13 -> 123080
A15: Financing:
A16: Borrowing | C16: 60000 | I16: =SUM(C16,E16,G16) -> 60000
A17: Repayment | E17: -50000 | G17: -10000 | I17: =SUM(C17,E17,G17) -> -60000
A18: Interest | E18: =-(60000*'Additional Information'!E39*2/12) -> -1200 | G18: =-(10000*'Additional Information'!E39*1/12) -> -100 | I18: =SUM(C18,E18,G18) -> -1300
A19: Total Financing | C19: =SUM(C16:C18) -> 60000 | E19: =SUM(E16:E18) -> -51200 | G19: =SUM(G16:G18) -> -10100 | I19: =SUM(C19,E19,G19) -> -1300
A20: Ending Balance | C20: =C14+C19 -> 50600 | E20: =E14+E19 -> 53040 | G20: =G14+G19 -> 121780 | I20: =SUM(I14+I19) -> 121780

Sheet Budgeted Income Statement
A1: Albert Enterprises
A2: Budgeted Income Statement
A3: For the 3 months ending
A4: 45016
A6: Sales (120,000 units @ $60) | E6: ='Sales Budget'!I5 -> 7200000
A7: Less: Cost of goods sold (120,000 units @ $44.76) | E7: =B22 -> 5374285.7
A8: Gross Margin | E8: =E6-E7 -> 1825714.3
A9: Less: Selling and Administrative (SG&A) Expenses | E9: ='Selling Admin Budget'!I7 -> 600000
A10: Operating Income | E10: =E8-E9 -> 1225714.3
A11: Interest Expense | E11: =-('Cash Budget'!I18) -> 1300
A12: Net Income | E12: =E10-E11 -> 1224414.3
A17: Supplemental Calculations:
A18: Cost of Beg. Finished Goods | B18: ='2022 Balance Sheet'!E9 -> 540000 | C18: From BS
A19: Add: Cost of units produced | B19: ='Production Budget'!I7*'Ending Finished Goods Inventory'!G10 -> 5640000 | C19: Production x FG Rate
A20: Cost of Goods Available for Sale | B20: =B18+B19 -> 6180000
A21: Less: Cost of Ending FG Inventory | B21: ='Ending Finished Goods Inventory'!G11 -> 805714.29 | C21: Ending FG
A22: COGS | B22: =B20-B21 -> 5374285.7

Sheet Budgeted Balance Sheet
A1: Albert Enterprises
A2: Balance Sheet
A3: 45016
A5: Assets | E5: =A3 -> 45016
A6: Cash | E6: ='Cash Budget'!I20 -> 121780
A7: Accounts Receivable | E7: ='Expected Cash Collections'!I22 -> 2580000
A8: Raw Materials inventory | E8: =C24*C25 -> 196800
A9: Finished Goods inventory | E9: ='Ending Finished Goods Inventory'!G11 -> 805714.29
A10: Total Current Assets | E10: =SUM(E6:E9) -> 3704294.3
A11: Net Property, Plant, and Equipment | E11: ='2022 Balance Sheet'!E11+'Additional Information'!E34-'Mfg OH Budget'!I8-'Selling Admin Budget'!I8 -> 1365000
A12: Total Assets | E12: =E10+E11 -> 5069294.3
A13: Liabilities & Stockholder Equity
A14: Accounts Payable | E14: ='Cash Disbursement Mats'!I15 -> 782880
A15: Total Current Liabilities | E15: =SUM(E14) -> 782880
A16: Notes Payable | E16: 0
A17: Total Liabilities | E17: =E15+E16 -> 782880
A18: Common Stock | E18: 1500000
A19: Retained Earnings | E19: ='2022 Balance Sheet'!E19+'Budgeted Income Statement'!E12-'Additional Information'!E35 -> 2786414.3
A20: Total Liabilities & Stockholder Equity | E20: =SUM(E17:E19) -> 5069294.3
A23: Supplemental Calculations:
A24: Raw Materials inventory | C24: ='Direct Mats Budget'!I6 -> 24600
A25: Direct Materials Cost | C25: ='Ending Finished Goods Inventory'!F4 -> 8
A27: Balance Discrepancy Identified | C27: =E12-E20 -> 0
